--- Logging error ---
Traceback (most recent call last):
  File "/blue/hulcr/gmarais/PhD/phase_2_baseline/0_object_detection/1_yolov10/train/yolov10_train_5_folds.py", line 168, in train_single_fold
    results = model.train(**current_train_params)
              ^^^^^^^^^^^^^^^^^^^^^^^^^^^^^^^^^^^
  File "/blue/hulcr/gmarais/conda/envs/EEL/lib/python3.11/site-packages/ultralytics/engine/model.py", line 793, in train
    self.trainer.train()
  File "/blue/hulcr/gmarais/conda/envs/EEL/lib/python3.11/site-packages/ultralytics/engine/trainer.py", line 211, in train
    self._do_train(world_size)
  File "/blue/hulcr/gmarais/conda/envs/EEL/lib/python3.11/site-packages/ultralytics/engine/trainer.py", line 332, in _do_train
    self._setup_train(world_size)
  File "/blue/hulcr/gmarais/conda/envs/EEL/lib/python3.11/site-packages/ultralytics/engine/trainer.py", line 291, in _setup_train
    self.train_loader = self.get_dataloader(
                        ^^^^^^^^^^^^^^^^^^^^
  File "/blue/hulcr/gmarais/conda/envs/EEL/lib/python3.11/site-packages/ultralytics/models/yolo/detect/train.py", line 82, in get_dataloader
    dataset = self.build_dataset(dataset_path, mode, batch_size)
              ^^^^^^^^^^^^^^^^^^^^^^^^^^^^^^^^^^^^^^^^^^^^^^^^^^
  File "/blue/hulcr/gmarais/conda/envs/EEL/lib/python3.11/site-packages/ultralytics/models/yolo/detect/train.py", line 65, in build_dataset
    return build_yolo_dataset(self.args, img_path, batch, self.data, mode=mode, rect=mode == "val", stride=gs)
           ^^^^^^^^^^^^^^^^^^^^^^^^^^^^^^^^^^^^^^^^^^^^^^^^^^^^^^^^^^^^^^^^^^^^^^^^^^^^^^^^^^^^^^^^^^^^^^^^^^^
  File "/blue/hulcr/gmarais/conda/envs/EEL/lib/python3.11/site-packages/ultralytics/data/build.py", line 109, in build_yolo_dataset
    return dataset(
           ^^^^^^^^
  File "/blue/hulcr/gmarais/conda/envs/EEL/lib/python3.11/site-packages/ultralytics/data/dataset.py", line 87, in __init__
    super().__init__(*args, channels=self.data["channels"], **kwargs)
  File "/blue/hulcr/gmarais/conda/envs/EEL/lib/python3.11/site-packages/ultralytics/data/base.py", line 140, in __init__
    self.cache_images()
  File "/blue/hulcr/gmarais/conda/envs/EEL/lib/python3.11/site-packages/ultralytics/data/base.py", line 268, in cache_images
    for i, x in pbar:
  File "/blue/hulcr/gmarais/conda/envs/EEL/lib/python3.11/site-packages/tqdm/std.py", line 1181, in __iter__
    for obj in iterable:
  File "/blue/hulcr/gmarais/conda/envs/EEL/lib/python3.11/multiprocessing/pool.py", line 873, in next
    raise value
  File "/blue/hulcr/gmarais/conda/envs/EEL/lib/python3.11/multiprocessing/pool.py", line 125, in worker
    result = (True, func(*args, **kwds))
                    ^^^^^^^^^^^^^^^^^^^
  File "/blue/hulcr/gmarais/conda/envs/EEL/lib/python3.11/site-packages/ultralytics/data/base.py", line 281, in cache_images_to_disk
    np.save(f.as_posix(), imread(self.im_files[i]), allow_pickle=False)
  File "/blue/hulcr/gmarais/conda/envs/EEL/lib/python3.11/site-packages/numpy/lib/_npyio_impl.py", line 574, in save
    format.write_array(fid, arr, allow_pickle=allow_pickle,
  File "/blue/hulcr/gmarais/conda/envs/EEL/lib/python3.11/site-packages/numpy/lib/format.py", line 757, in write_array
    array.tofile(fp)
OSError: 38707200 requested and 65408 written

During handling of the above exception, another exception occurred:

Traceback (most recent call last):
  File "/blue/hulcr/gmarais/conda/envs/EEL/lib/python3.11/logging/__init__.py", line 1114, in emit
    self.flush()
  File "/blue/hulcr/gmarais/conda/envs/EEL/lib/python3.11/logging/__init__.py", line 1094, in flush
    self.stream.flush()
OSError: [Errno 122] Disk quota exceeded

During handling of the above exception, another exception occurred:

Traceback (most recent call last):
  File "/blue/hulcr/gmarais/PhD/phase_2_baseline/0_object_detection/1_yolov10/train/yolov10_train_5_folds.py", line 176, in train_single_fold
    fold_py_logger.error(f"An error occurred during training: {e}", exc_info=True)
  File "/blue/hulcr/gmarais/conda/envs/EEL/lib/python3.11/logging/__init__.py", line 1518, in error
    self._log(ERROR, msg, args, **kwargs)
  File "/blue/hulcr/gmarais/conda/envs/EEL/lib/python3.11/logging/__init__.py", line 1634, in _log
    self.handle(record)
  File "/blue/hulcr/gmarais/conda/envs/EEL/lib/python3.11/logging/__init__.py", line 1644, in handle
    self.callHandlers(record)
  File "/blue/hulcr/gmarais/conda/envs/EEL/lib/python3.11/logging/__init__.py", line 1706, in callHandlers
    hdlr.handle(record)
  File "/blue/hulcr/gmarais/conda/envs/EEL/lib/python3.11/logging/__init__.py", line 978, in handle
    self.emit(record)
  File "/blue/hulcr/gmarais/conda/envs/EEL/lib/python3.11/logging/__init__.py", line 1230, in emit
    StreamHandler.emit(self, record)
  File "/blue/hulcr/gmarais/conda/envs/EEL/lib/python3.11/logging/__init__.py", line 1118, in emit
    self.handleError(record)
  File "/blue/hulcr/gmarais/conda/envs/EEL/lib/python3.11/logging/__init__.py", line 1031, in handleError
    sys.stderr.write('--- Logging error ---\n')
ValueError: I/O operation on closed file.

During handling of the above exception, another exception occurred:

Traceback (most recent call last):
  File "/blue/hulcr/gmarais/conda/envs/EEL/lib/python3.11/logging/__init__.py", line 1114, in emit
    self.flush()
  File "/blue/hulcr/gmarais/conda/envs/EEL/lib/python3.11/logging/__init__.py", line 1094, in flush
    self.stream.flush()
OSError: [Errno 122] Disk quota exceeded
Call stack:
  File "<string>", line 1, in <module>
  File "/blue/hulcr/gmarais/conda/envs/EEL/lib/python3.11/multiprocessing/spawn.py", line 122, in spawn_main
    exitcode = _main(fd, parent_sentinel)
  File "/blue/hulcr/gmarais/conda/envs/EEL/lib/python3.11/multiprocessing/spawn.py", line 135, in _main
    return self._bootstrap(parent_sentinel)
  File "/blue/hulcr/gmarais/conda/envs/EEL/lib/python3.11/multiprocessing/process.py", line 314, in _bootstrap
    self.run()
  File "/blue/hulcr/gmarais/conda/envs/EEL/lib/python3.11/multiprocessing/process.py", line 108, in run
    self._target(*self._args, **self._kwargs)
  File "/blue/hulcr/gmarais/PhD/phase_2_baseline/0_object_detection/1_yolov10/train/yolov10_train_5_folds.py", line 187, in train_single_fold
    fold_py_logger.info("Restored stdout/stderr for this fold process.")
Message: 'Restored stdout/stderr for this fold process.'
Arguments: ()
Process Fold-5_GPU-4:
Traceback (most recent call last):
  File "/blue/hulcr/gmarais/PhD/phase_2_baseline/0_object_detection/1_yolov10/train/yolov10_train_5_folds.py", line 168, in train_single_fold
    results = model.train(**current_train_params)
              ^^^^^^^^^^^^^^^^^^^^^^^^^^^^^^^^^^^
  File "/blue/hulcr/gmarais/conda/envs/EEL/lib/python3.11/site-packages/ultralytics/engine/model.py", line 793, in train
    self.trainer.train()
  File "/blue/hulcr/gmarais/conda/envs/EEL/lib/python3.11/site-packages/ultralytics/engine/trainer.py", line 211, in train
    self._do_train(world_size)
  File "/blue/hulcr/gmarais/conda/envs/EEL/lib/python3.11/site-packages/ultralytics/engine/trainer.py", line 332, in _do_train
    self._setup_train(world_size)
  File "/blue/hulcr/gmarais/conda/envs/EEL/lib/python3.11/site-packages/ultralytics/engine/trainer.py", line 291, in _setup_train
    self.train_loader = self.get_dataloader(
                        ^^^^^^^^^^^^^^^^^^^^
  File "/blue/hulcr/gmarais/conda/envs/EEL/lib/python3.11/site-packages/ultralytics/models/yolo/detect/train.py", line 82, in get_dataloader
    dataset = self.build_dataset(dataset_path, mode, batch_size)
              ^^^^^^^^^^^^^^^^^^^^^^^^^^^^^^^^^^^^^^^^^^^^^^^^^^
  File "/blue/hulcr/gmarais/conda/envs/EEL/lib/python3.11/site-packages/ultralytics/models/yolo/detect/train.py", line 65, in build_dataset
    return build_yolo_dataset(self.args, img_path, batch, self.data, mode=mode, rect=mode == "val", stride=gs)
           ^^^^^^^^^^^^^^^^^^^^^^^^^^^^^^^^^^^^^^^^^^^^^^^^^^^^^^^^^^^^^^^^^^^^^^^^^^^^^^^^^^^^^^^^^^^^^^^^^^^
  File "/blue/hulcr/gmarais/conda/envs/EEL/lib/python3.11/site-packages/ultralytics/data/build.py", line 109, in build_yolo_dataset
    return dataset(
           ^^^^^^^^
  File "/blue/hulcr/gmarais/conda/envs/EEL/lib/python3.11/site-packages/ultralytics/data/dataset.py", line 87, in __init__
    super().__init__(*args, channels=self.data["channels"], **kwargs)
  File "/blue/hulcr/gmarais/conda/envs/EEL/lib/python3.11/site-packages/ultralytics/data/base.py", line 140, in __init__
    self.cache_images()
  File "/blue/hulcr/gmarais/conda/envs/EEL/lib/python3.11/site-packages/ultralytics/data/base.py", line 268, in cache_images
    for i, x in pbar:
  File "/blue/hulcr/gmarais/conda/envs/EEL/lib/python3.11/site-packages/tqdm/std.py", line 1181, in __iter__
    for obj in iterable:
  File "/blue/hulcr/gmarais/conda/envs/EEL/lib/python3.11/multiprocessing/pool.py", line 873, in next
    raise value
  File "/blue/hulcr/gmarais/conda/envs/EEL/lib/python3.11/multiprocessing/pool.py", line 125, in worker
    result = (True, func(*args, **kwds))
                    ^^^^^^^^^^^^^^^^^^^
  File "/blue/hulcr/gmarais/conda/envs/EEL/lib/python3.11/site-packages/ultralytics/data/base.py", line 281, in cache_images_to_disk
    np.save(f.as_posix(), imread(self.im_files[i]), allow_pickle=False)
  File "/blue/hulcr/gmarais/conda/envs/EEL/lib/python3.11/site-packages/numpy/lib/_npyio_impl.py", line 574, in save
    format.write_array(fid, arr, allow_pickle=allow_pickle,
  File "/blue/hulcr/gmarais/conda/envs/EEL/lib/python3.11/site-packages/numpy/lib/format.py", line 757, in write_array
    array.tofile(fp)
OSError: 38707200 requested and 65408 written

During handling of the above exception, another exception occurred:

Traceback (most recent call last):
  File "/blue/hulcr/gmarais/conda/envs/EEL/lib/python3.11/logging/__init__.py", line 1114, in emit
    self.flush()
  File "/blue/hulcr/gmarais/conda/envs/EEL/lib/python3.11/logging/__init__.py", line 1094, in flush
    self.stream.flush()
OSError: [Errno 122] Disk quota exceeded

During handling of the above exception, another exception occurred:

Traceback (most recent call last):
  File "/blue/hulcr/gmarais/PhD/phase_2_baseline/0_object_detection/1_yolov10/train/yolov10_train_5_folds.py", line 176, in train_single_fold
    fold_py_logger.error(f"An error occurred during training: {e}", exc_info=True)
  File "/blue/hulcr/gmarais/conda/envs/EEL/lib/python3.11/logging/__init__.py", line 1518, in error
    self._log(ERROR, msg, args, **kwargs)
  File "/blue/hulcr/gmarais/conda/envs/EEL/lib/python3.11/logging/__init__.py", line 1634, in _log
    self.handle(record)
  File "/blue/hulcr/gmarais/conda/envs/EEL/lib/python3.11/logging/__init__.py", line 1644, in handle
    self.callHandlers(record)
  File "/blue/hulcr/gmarais/conda/envs/EEL/lib/python3.11/logging/__init__.py", line 1706, in callHandlers
    hdlr.handle(record)
  File "/blue/hulcr/gmarais/conda/envs/EEL/lib/python3.11/logging/__init__.py", line 978, in handle
    self.emit(record)
  File "/blue/hulcr/gmarais/conda/envs/EEL/lib/python3.11/logging/__init__.py", line 1230, in emit
    StreamHandler.emit(self, record)
  File "/blue/hulcr/gmarais/conda/envs/EEL/lib/python3.11/logging/__init__.py", line 1118, in emit
    self.handleError(record)
  File "/blue/hulcr/gmarais/conda/envs/EEL/lib/python3.11/logging/__init__.py", line 1031, in handleError
    sys.stderr.write('--- Logging error ---\n')
ValueError: I/O operation on closed file.

During handling of the above exception, another exception occurred:

Traceback (most recent call last):
  File "/blue/hulcr/gmarais/conda/envs/EEL/lib/python3.11/logging/__init__.py", line 1192, in close
    self.flush()
  File "/blue/hulcr/gmarais/conda/envs/EEL/lib/python3.11/logging/__init__.py", line 1094, in flush
    self.stream.flush()
OSError: [Errno 122] Disk quota exceeded

During handling of the above exception, another exception occurred:

OSError: [Errno 122] Disk quota exceeded

During handling of the above exception, another exception occurred:

Traceback (most recent call last):
  File "/blue/hulcr/gmarais/conda/envs/EEL/lib/python3.11/multiprocessing/process.py", line 314, in _bootstrap
    self.run()
  File "/blue/hulcr/gmarais/conda/envs/EEL/lib/python3.11/multiprocessing/process.py", line 108, in run
    self._target(*self._args, **self._kwargs)
  File "/blue/hulcr/gmarais/PhD/phase_2_baseline/0_object_detection/1_yolov10/train/yolov10_train_5_folds.py", line 190, in train_single_fold
    handler.close()
  File "/blue/hulcr/gmarais/conda/envs/EEL/lib/python3.11/logging/__init__.py", line 1197, in close
    stream.close()
OSError: [Errno 122] Disk quota exceeded
--- Logging error ---
Traceback (most recent call last):
  File "/blue/hulcr/gmarais/PhD/phase_2_baseline/0_object_detection/1_yolov10/train/yolov10_train_5_folds.py", line 168, in train_single_fold
    results = model.train(**current_train_params)
              ^^^^^^^^^^^^^^^^^^^^^^^^^^^^^^^^^^^
  File "/blue/hulcr/gmarais/conda/envs/EEL/lib/python3.11/site-packages/ultralytics/engine/model.py", line 793, in train
    self.trainer.train()
  File "/blue/hulcr/gmarais/conda/envs/EEL/lib/python3.11/site-packages/ultralytics/engine/trainer.py", line 211, in train
    self._do_train(world_size)
  File "/blue/hulcr/gmarais/conda/envs/EEL/lib/python3.11/site-packages/ultralytics/engine/trainer.py", line 332, in _do_train
    self._setup_train(world_size)
  File "/blue/hulcr/gmarais/conda/envs/EEL/lib/python3.11/site-packages/ultralytics/engine/trainer.py", line 291, in _setup_train
    self.train_loader = self.get_dataloader(
                        ^^^^^^^^^^^^^^^^^^^^
  File "/blue/hulcr/gmarais/conda/envs/EEL/lib/python3.11/site-packages/ultralytics/models/yolo/detect/train.py", line 82, in get_dataloader
    dataset = self.build_dataset(dataset_path, mode, batch_size)
              ^^^^^^^^^^^^^^^^^^^^^^^^^^^^^^^^^^^^^^^^^^^^^^^^^^
  File "/blue/hulcr/gmarais/conda/envs/EEL/lib/python3.11/site-packages/ultralytics/models/yolo/detect/train.py", line 65, in build_dataset
    return build_yolo_dataset(self.args, img_path, batch, self.data, mode=mode, rect=mode == "val", stride=gs)
           ^^^^^^^^^^^^^^^^^^^^^^^^^^^^^^^^^^^^^^^^^^^^^^^^^^^^^^^^^^^^^^^^^^^^^^^^^^^^^^^^^^^^^^^^^^^^^^^^^^^
  File "/blue/hulcr/gmarais/conda/envs/EEL/lib/python3.11/site-packages/ultralytics/data/build.py", line 109, in build_yolo_dataset
    return dataset(
           ^^^^^^^^
  File "/blue/hulcr/gmarais/conda/envs/EEL/lib/python3.11/site-packages/ultralytics/data/dataset.py", line 87, in __init__
    super().__init__(*args, channels=self.data["channels"], **kwargs)
  File "/blue/hulcr/gmarais/conda/envs/EEL/lib/python3.11/site-packages/ultralytics/data/base.py", line 140, in __init__
    self.cache_images()
  File "/blue/hulcr/gmarais/conda/envs/EEL/lib/python3.11/site-packages/ultralytics/data/base.py", line 268, in cache_images
    for i, x in pbar:
  File "/blue/hulcr/gmarais/conda/envs/EEL/lib/python3.11/site-packages/tqdm/std.py", line 1181, in __iter__
    for obj in iterable:
  File "/blue/hulcr/gmarais/conda/envs/EEL/lib/python3.11/multiprocessing/pool.py", line 873, in next
    raise value
  File "/blue/hulcr/gmarais/conda/envs/EEL/lib/python3.11/multiprocessing/pool.py", line 125, in worker
    result = (True, func(*args, **kwds))
                    ^^^^^^^^^^^^^^^^^^^
  File "/blue/hulcr/gmarais/conda/envs/EEL/lib/python3.11/site-packages/ultralytics/data/base.py", line 281, in cache_images_to_disk
    np.save(f.as_posix(), imread(self.im_files[i]), allow_pickle=False)
  File "/blue/hulcr/gmarais/conda/envs/EEL/lib/python3.11/site-packages/numpy/lib/_npyio_impl.py", line 574, in save
    format.write_array(fid, arr, allow_pickle=allow_pickle,
  File "/blue/hulcr/gmarais/conda/envs/EEL/lib/python3.11/site-packages/numpy/lib/format.py", line 757, in write_array
    array.tofile(fp)
OSError: 53747712 requested and 65408 written

During handling of the above exception, another exception occurred:

Traceback (most recent call last):
  File "/blue/hulcr/gmarais/conda/envs/EEL/lib/python3.11/logging/__init__.py", line 1114, in emit
    self.flush()
  File "/blue/hulcr/gmarais/conda/envs/EEL/lib/python3.11/logging/__init__.py", line 1094, in flush
    self.stream.flush()
OSError: [Errno 122] Disk quota exceeded

During handling of the 