CRITICAL ERROR in Fold-1_GPU-0: Dataset '/blue/hulcr/gmarais/PhD/IBBI_work/phase_1_data/2_object_detection_phase_2/ultralytics/cv_iteration_1/data.yaml' error ❌ Dataset '/blue/hulcr/gmarais/PhD/IBBI_work/phase_1_data/2_object_detection_phase_2/ultralytics/cv_iteration_1/data.yaml' images not found, missing path '/blue/hulcr/gmarais/PhD/phase_1_data/2_object_detection_phase_2/ultralytics/cv_iteration_1/images/val'
Note dataset download directory is '/blue/hulcr/gmarais/PhD/IBBI_work/phase_2_baseline/0_object_detect/8_rtdetr/train/datasets'. You can update this in '/home/gmarais/.config/Ultralytics/settings.json'
See script log ./results_rtdetr-x/fold_1/script_log_fold_1_gpu_0.log and Ultralytics log ./results_rtdetr-x/fold_1/ultralytics_output_fold_1_gpu_0.log for details.
Process Fold-1_GPU-0:
Traceback (most recent call last):
  File "/blue/hulcr/gmarais/conda/envs/EEL/lib/python3.11/site-packages/ultralytics/engine/trainer.py", line 587, in get_dataset
    data = check_det_dataset(self.args.data)
           ^^^^^^^^^^^^^^^^^^^^^^^^^^^^^^^^^
  File "/blue/hulcr/gmarais/conda/envs/EEL/lib/python3.11/site-packages/ultralytics/data/utils.py", line 454, in check_det_dataset
    raise FileNotFoundError(m)
FileNotFoundError: Dataset '/blue/hulcr/gmarais/PhD/IBBI_work/phase_1_data/2_object_detection_phase_2/ultralytics/cv_iteration_1/data.yaml' images not found, missing path '/blue/hulcr/gmarais/PhD/phase_1_data/2_object_detection_phase_2/ultralytics/cv_iteration_1/images/val'
Note dataset download directory is '/blue/hulcr/gmarais/PhD/IBBI_work/phase_2_baseline/0_object_detect/8_rtdetr/train/datasets'. You can update this in '/home/gmarais/.config/Ultralytics/settings.json'

The above exception was the direct cause of the following exception:

Traceback (most recent call last):
  File "/blue/hulcr/gmarais/conda/envs/EEL/lib/python3.11/multiprocessing/process.py", line 314, in _bootstrap
    self.run()
  File "/blue/hulcr/gmarais/conda/envs/EEL/lib/python3.11/multiprocessing/process.py", line 108, in run
    self._target(*self._args, **self._kwargs)
  File "/blue/hulcr/gmarais/PhD/IBBI_work/phase_2_baseline/0_object_detect/8_rtdetr/train/rtdetr_5fold.py", line 179, in train_single_fold
    results = model.train(**current_train_params)
              ^^^^^^^^^^^^^^^^^^^^^^^^^^^^^^^^^^^
  File "/blue/hulcr/gmarais/conda/envs/EEL/lib/python3.11/site-packages/ultralytics/engine/model.py", line 787, in train
    self.trainer = (trainer or self._smart_load("trainer"))(overrides=args, _callbacks=self.callbacks)
                   ^^^^^^^^^^^^^^^^^^^^^^^^^^^^^^^^^^^^^^^^^^^^^^^^^^^^^^^^^^^^^^^^^^^^^^^^^^^^^^^^^^^
  File "/blue/hulcr/gmarais/conda/envs/EEL/lib/python3.11/site-packages/ultralytics/engine/trainer.py", line 137, in __init__
    self.data = self.get_dataset()
                ^^^^^^^^^^^^^^^^^^
  File "/blue/hulcr/gmarais/conda/envs/EEL/lib/python3.11/site-packages/ultralytics/engine/trainer.py", line 591, in get_dataset
    raise RuntimeError(emojis(f"Dataset '{clean_url(self.args.data)}' error ❌ {e}")) from e
RuntimeError: Dataset '/blue/hulcr/gmarais/PhD/IBBI_work/phase_1_data/2_object_detection_phase_2/ultralytics/cv_iteration_1/data.yaml' error ❌ Dataset '/blue/hulcr/gmarais/PhD/IBBI_work/phase_1_data/2_object_detection_phase_2/ultralytics/cv_iteration_1/data.yaml' images not found, missing path '/blue/hulcr/gmarais/PhD/phase_1_data/2_object_detection_phase_2/ultralytics/cv_iteration_1/images/val'
Note dataset download directory is '/blue/hulcr/gmarais/PhD/IBBI_work/phase_2_baseline/0_object_detect/8_rtdetr/train/datasets'. You can update this in '/home/gmarais/.config/Ultralytics/settings.json'
CRITICAL ERROR in Fold-4_GPU-0: Dataset '/blue/hulcr/gmarais/PhD/IBBI_work/phase_1_data/2_object_detection_phase_2/ultralytics/cv_iteration_4/data.yaml' error ❌ Dataset '/blue/hulcr/gmarais/PhD/IBBI_work/phase_1_data/2_object_detection_phase_2/ultralytics/cv_iteration_4/data.yaml' images not found, missing path '/blue/hulcr/gmarais/PhD/phase_1_data/2_object_detection_phase_2/ultralytics/cv_iteration_4/images/val'
Note dataset download directory is '/blue/hulcr/gmarais/PhD/IBBI_work/phase_2_baseline/0_object_detect/8_rtdetr/train/datasets'. You can update this in '/home/gmarais/.config/Ultralytics/settings.json'
See script log ./results_rtdetr-x/fold_4/script_log_fold_4_gpu_0.log and Ultralytics log ./results_rtdetr-x/fold_4/ultralytics_output_fold_4_gpu_0.log for details.
Process Fold-4_GPU-0:
Traceback (most recent call last):
  File "/blue/hulcr/gmarais/conda/envs/EEL/lib/python3.11/site-packages/ultralytics/engine/trainer.py", line 587, in get_dataset
    data = check_det_dataset(self.args.data)
           ^^^^^^^^^^^^^^^^^^^^^^^^^^^^^^^^^
  File "/blue/hulcr/gmarais/conda/envs/EEL/lib/python3.11/site-packages/ultralytics/data/utils.py", line 454, in check_det_dataset
    raise FileNotFoundError(m)
FileNotFoundError: Dataset '/blue/hulcr/gmarais/PhD/IBBI_work/phase_1_data/2_object_detection_phase_2/ultralytics/cv_iteration_4/data.yaml' images not found, missing path '/blue/hulcr/gmarais/PhD/phase_1_data/2_object_detection_phase_2/ultralytics/cv_iteration_4/images/val'
Note dataset download directory is '/blue/hulcr/gmarais/PhD/IBBI_work/phase_2_baseline/0_object_detect/8_rtdetr/train/datasets'. You can update this in '/home/gmarais/.config/Ultralytics/settings.json'

The above exception was the direct cause of the following exception:

Traceback (most recent call last):
  File "/blue/hulcr/gmarais/conda/envs/EEL/lib/python3.11/multiprocessing/process.py", line 314, in _bootstrap
    self.run()
  File "/blue/hulcr/gmarais/conda/envs/EEL/lib/python3.11/multiprocessing/process.py", line 108, in run
    self._target(*self._args, **self._kwargs)
  File "/blue/hulcr/gmarais/PhD/IBBI_work/phase_2_baseline/0_object_detect/8_rtdetr/train/rtdetr_5fold.py", line 179, in train_single_fold
    results = model.train(**current_train_params)
              ^^^^^^^^^^^^^^^^^^^^^^^^^^^^^^^^^^^
  File "/blue/hulcr/gmarais/conda/envs/EEL/lib/python3.11/site-packages/ultralytics/engine/model.py", line 787, in train
    self.trainer = (trainer or self._smart_load("trainer"))(overrides=args, _callbacks=self.callbacks)
                   ^^^^^^^^^^^^^^^^^^^^^^^^^^^^^^^^^^^^^^^^^^^^^^^^^^^^^^^^^^^^^^^^^^^^^^^^^^^^^^^^^^^
  File "/blue/hulcr/gmarais/conda/envs/EEL/lib/python3.11/site-packages/ultralytics/engine/trainer.py", line 137, in __init__
    self.data = self.get_dataset()
                ^^^^^^^^^^^^^^^^^^
  File "/blue/hulcr/gmarais/conda/envs/EEL/lib/python3.11/site-packages/ultralytics/engine/trainer.py", line 591, in get_dataset
    raise RuntimeError(emojis(f"Dataset '{clean_url(self.args.data)}' error ❌ {e}")) from e
RuntimeError: Dataset '/blue/hulcr/gmarais/PhD/IBBI_work/phase_1_data/2_object_detection_phase_2/ultralytics/cv_iteration_4/data.yaml' error ❌ Dataset '/blue/hulcr/gmarais/PhD/IBBI_work/phase_1_data/2_object_detection_phase_2/ultralytics/cv_iteration_4/data.yaml' images not found, missing path '/blue/hulcr/gmarais/PhD/phase_1_data/2_object_detection_phase_2/ultralytics/cv_iteration_4/images/val'
Note dataset download directory is '/blue/hulcr/gmarais/PhD/IBBI_work/phase_2_baseline/0_object_detect/8_rtdetr/train/datasets'. You can update this in '/home/gmarais/.config/Ultralytics/settings.json'
CRITICAL ERROR in Fold-5_GPU-1: Dataset '/blue/hulcr/gmarais/PhD/IBBI_work/phase_1_data/2_object_detection_phase_2/ultralytics/cv_iteration_5/data.yaml' error ❌ Dataset '/blue/hulcr/gmarais/PhD/IBBI_work/phase_1_data/2_object_detection_phase_2/ultralytics/cv_iteration_5/data.yaml' images not found, missing path '/blue/hulcr/gmarais/PhD/phase_1_data/2_object_detection_phase_2/ultralytics/cv_iteration_5/images/val'
Note dataset download directory is '/blue/hulcr/gmarais/PhD/IBBI_work/phase_2_baseline/0_object_detect/8_rtdetr/train/datasets'. You can update this in '/home/gmarais/.config/Ultralytics/settings.json'
See script log ./results_rtdetr-x/fold_5/script_log_fold_5_gpu_1.log and Ultralytics log ./results_rtdetr-x/fold_5/ultralytics_output_fold_5_gpu_1.log for details.
Process Fold-5_GPU-1:
CRITICAL ERROR in Fold-3_GPU-2: Dataset '/blue/hulcr/gmarais/PhD/IBBI_work/phase_1_data/2_object_detection_phase_2/ultralytics/cv_iteration_3/data.yaml' error ❌ Dataset '/blue/hulcr/gmarais/PhD/IBBI_work/phase_1_data/2_object_detection_phase_2/ultralytics/cv_iteration_3/data.yaml' images not found, missing path '/blue/hulcr/gmarais/PhD/phase_1_data/2_object_detection_phase_2/ultralytics/cv_iteration_3/images/val'
Note dataset download directory is '/blue/hulcr/gmarais/PhD/phase_2_baseline/0_object_detection/8_rtdetr/train/datasets'. You can update this in '/home/gmarais/.config/Ultralytics/settings.json'
See script log ./results_rtdetr-x/fold_3/script_log_fold_3_gpu_2.log and Ultralytics log ./results_rtdetr-x/fold_3/ultralytics_output_fold_3_gpu_2.log for details.
Process Fold-3_GPU-2:
Traceback (most recent call last):
  File "/blue/hulcr/gmarais/conda/envs/EEL/lib/python3.11/site-packages/ultralytics/engine/trainer.py", line 587, in get_dataset
    data = check_det_dataset(self.args.data)
           ^^^^^^^^^^^^^^^^^^^^^^^^^^^^^^^^^
  File "/blue/hulcr/gmarais/conda/envs/EEL/lib/python3.11/site-packages/ultralytics/data/utils.py", line 454, in check_det_dataset
    raise FileNotFoundError(m)
FileNotFoundError: Dataset '/blue/hulcr/gmarais/PhD/IBBI_work/phase_1_data/2_object_detection_phase_2/ultralytics/cv_iteration_5/data.yaml' images not found, missing path '/blue/hulcr/gmarais/PhD/phase_1_data/2_object_detection_phase_2/ultralytics/cv_iteration_5/images/val'
Note dataset download directory is '/blue/hulcr/gmarais/PhD/IBBI_work/phase_2_baseline/0_object_detect/8_rtdetr/train/datasets'. You can update this in '/home/gmarais/.config/Ultralytics/settings.json'

The above exception was the direct cause of the following exception:

Traceback (most recent call last):
  File "/blue/hulcr/gmarais/conda/envs/EEL/lib/python3.11/multiprocessing/process.py", line 314, in _bootstrap
    self.run()
  File "/blue/hulcr/gmarais/conda/envs/EEL/lib/python3.11/multiprocessing/process.py", line 108, in run
    self._target(*self._args, **self._kwargs)
  File "/blue/hulcr/gmarais/PhD/IBBI_work/phase_2_baseline/0_object_detect/8_rtdetr/train/rtdetr_5fold.py", line 179, in train_single_fold
    results = model.train(**current_train_params)
              ^^^^^^^^^^^^^^^^^^^^^^^^^^^^^^^^^^^
  File "/blue/hulcr/gmarais/conda/envs/EEL/lib/python3.11/site-packages/ultralytics/engine/model.py", line 787, in train
    self.trainer = (trainer or self._smart_load("trainer"))(overrides=args, _callbacks=self.callbacks)
                   ^^^^^^^^^^^^^^^^^^^^^^^^^^^^^^^^^^^^^^^^^^^^^^^^^^^^^^^^^^^^^^^^^^^^^^^^^^^^^^^^^^^
  File "/blue/hulcr/gmarais/conda/envs/EEL/lib/python3.11/site-packages/ultralytics/engine/trainer.py", line 137, in __init__
    self.data = self.get_dataset()
                ^^^^^^^^^^^^^^^^^^
  File "/blue/hulcr/gmarais/conda/envs/EEL/lib/python3.11/site-packages/ultralytics/engine/trainer.py", line 591, in get_dataset
    raise RuntimeError(emojis(f"Dataset '{clean_url(self.args.data)}' error ❌ {e}")) from e
RuntimeError: Dataset '/blue/hulcr/gmarais/PhD/IBBI_work/phase_1_data/2_object_detection_phase_2/ultralytics/cv_iteration_5/data.yaml' error ❌ Dataset '/blue/hulcr/gmarais/PhD/IBBI_work/phase_1_data/2_object_detection_phase_2/ultralytics/cv_iteration_5/data.yaml' images not found, missing path '/blue/hulcr/gmarais/PhD/phase_1_data/2_object_detection_phase_2/ultralytics/cv_iteration_5/images/val'
Note dataset download directory is '/blue/hulcr/gmarais/PhD/IBBI_work/phase_2_baseline/0_object_detect/8_rtdetr/train/datasets'. You can update this in '/home/gmarais/.config/Ultralytics/settings.json'
Traceback (most recent call last):
  File "/blue/hulcr/gmarais/conda/envs/EEL/lib/python3.11/site-packages/ultralytics/engine/trainer.py", line 587, in get_dataset
    data = check_det_dataset(self.args.data)
           ^^^^^^^^^^^^^^^^^^^^^^^^^^^^^^^^^
  File "/blue/hulcr/gmarais/conda/envs/EEL/lib/python3.11/site-packages/ultralytics/data/utils.py", line 454, in check_det_dataset
    raise FileNotFoundError(m)
FileNotFoundError: Dataset '/blue/hulcr/gmarais/PhD/IBBI_work/phase_1_data/2_object_detection_phase_2/ultralytics/cv_iteration_3/data.yaml' images not found, missing path '/blue/hulcr/gmarais/PhD/phase_1_data/2_object_detection_phase_2/ultralytics/cv_iteration_3/images/val'
Note dataset download directory is '/blue/hulcr/gmarais/PhD/phase_2_baseline/0_object_detection/8_rtdetr/train/datasets'. You can update this in '/home/gmarais/.config/Ultralytics/settings.json'

The above exception was the direct cause of the following exception:

Traceback (most recent call last):
  File "/blue/hulcr/gmarais/conda/envs/EEL/lib/python3.11/multiprocessing/process.py", line 314, in _bootstrap
    self.run()
  File "/blue/hulcr/gmarais/conda/envs/EEL/lib/python3.11/multiprocessing/process.py", line 108, in run
    self._target(*self._args, **self._kwargs)
  File "/blue/hulcr/gmarais/PhD/IBBI_work/phase_2_baseline/0_object_detect/8_rtdetr/train/rtdetr_5fold.py", line 179, in train_single_fold
    results = model.train(**current_train_params)
              ^^^^^^^^^^^^^^^^^^^^^^^^^^^^^^^^^^^
  File "/blue/hulcr/gmarais/conda/envs/EEL/lib/python3.11/site-packages/ultralytics/engine/model.py", line 787, in train
    self.trainer = (trainer or self._smart_load("trainer"))(overrides=args, _callbacks=self.callbacks)
                   ^^^^^^^^^^^^^^^^^^^^^^^^^^^^^^^^^^^^^^^^^^^^^^^^^^^^^^^^^^^^^^^^^^^^^^^^^^^^^^^^^^^
  File "/blue/hulcr/gmarais/conda/envs/EEL/lib/python3.11/site-packages/ultralytics/engine/trainer.py", line 137, in __init__
    self.data = self.get_dataset()
                ^^^^^^^^^^^^^^^^^^
  File "/blue/hulcr/gmarais/conda/envs/EEL/lib/python3.11/site-packages/ultralytics/engine/trainer.py", line 591, in get_dataset
    raise RuntimeError(emojis(f"Dataset '{clean_url(self.args.data)}' error ❌ {e}")) from e
RuntimeError: Dataset '/blue/hulcr/gmarais/PhD/IBBI_work/phase_1_data/2_object_detection_phase_2/ultralytics/cv_iteration_3/data.yaml' error ❌ Dataset '/blue/hulcr/gmarais/PhD/IBBI_work/phase_1_data/2_object_detection_phase_2/ultralytics/cv_iteration_3/data.yaml' images not found, missing path '/blue/hulcr/gmarais/PhD/phase_1_data/2_object_detection_phase_2/ultralytics/cv_iteration_3/images/val'
Note dataset download directory is '/blue/hulcr/gmarais/PhD/phase_2_baseline/0_object_detection/8_rtdetr/train/datasets'. You can update this in '/home/gmarais/.config/Ultralytics/settings.json'
CRITICAL ERROR in Fold-2_GPU-1: Dataset '/blue/hulcr/gmarais/PhD/IBBI_work/phase_1_data/2_object_detection_phase_2/ultralytics/cv_iteration_2/data.yaml' error ❌ Dataset '/blue/hulcr/gmarais/PhD/IBBI_work/phase_1_data/2_object_detection_phase_2/ultralytics/cv_iteration_2/data.yaml' images not found, missing path '/blue/hulcr/gmarais/PhD/phase_1_data/2_object_detection_phase_2/ultralytics/cv_iteration_2/images/val'
Note dataset download directory is '/blue/hulcr/gmarais/PhD/phase_2_baseline/0_object_detection/8_rtdetr/train/datasets'. You can update this in '/home/gmarais/.config/Ultralytics/settings.json'
See script log ./results_rtdetr-x/fold_2/script_log_fold_2_gpu_1.log and Ultralytics log ./results_rtdetr-x/fold_2/ultralytics_output_fold_2_gpu_1.log for details.
Process Fold-2_GPU-1:
Traceback (most recent call last):
  File "/blue/hulcr/gmarais/conda/envs/EEL/lib/python3.11/site-packages/ultralytics/engine/trainer.py", line 587, in get_dataset
    data = check_det_dataset(self.args.data)
           ^^^^^^^^^^^^^^^^^^^^^^^^^^^^^^^^^
  File "/blue/hulcr/gmarais/conda/envs/EEL/lib/python3.11/site-packages/ultralytics/data/utils.py", line 454, in check_det_dataset
    raise FileNotFoundError(m)
FileNotFoundError: Dataset '/blue/hulcr/gmarais/PhD/IBBI_work/phase_1_data/2_object_detection_phase_2/ultralytics/cv_iteration_2/data.yaml' images not found, missing path '/blue/hulcr/gmarais/PhD/phase_1_data/2_object_detection_phase_2/ultralytics/cv_iteration_2/images/val'
Note dataset download directory is '/blue/hulcr/gmarais/PhD/phase_2_baseline/0_object_detection/8_rtdetr/train/datasets'. You can update this in '/home/gmarais/.config/Ultralytics/settings.json'

The above exception was the direct cause of the following exception:

Traceback (most recent call last):
  File "/blue/hulcr/gmarais/conda/envs/EEL/lib/python3.11/multiprocessing/process.py", line 314, in _bootstrap
    self.run()
  File "/blue/hulcr/gmarais/conda/envs/EEL/lib/python3.11/multiprocessing/process.py", line 108, in run
    self._target(*self._args, **self._kwargs)
  File "/blue/hulcr/gmarais/PhD/IBBI_work/phase_2_baseline/0_object_detect/8_rtdetr/train/rtdetr_5fold.py", line 179, in train_single_fold
    results = model.train(**current_train_params)
              ^^^^^^^^^^^^^^^^^^^^^^^^^^^^^^^^^^^
  File "/blue/hulcr/gmarais/conda/envs/EEL/lib/python3.11/site-packages/ultralytics/engine/model.py", line 787, in train
    self.trainer = (trainer or self._smart_load("trainer"))(overrides=args, _callbacks=self.callbacks)
                   ^^^^^^^^^^^^^^^^^^^^^^^^^^^^^^^^^^^^^^^^^^^^^^^^^^^^^^^^^^^^^^^^^^^^^^^^^^^^^^^^^^^
  File "/blue/hulcr/gmarais/conda/envs/EEL/lib/python3.11/site-packages/ultralytics/engine/trainer.py", line 137, in __init__
    self.data = self.get_dataset()
                ^^^^^^^^^^^^^^^^^^
  File "/blue/hulcr/gmarais/conda/envs/EEL/lib/python3.11/site-packages/ultralytics/engine/trainer.py", line 591, in get_dataset
    raise RuntimeError(emojis(f"Dataset '{clean_url(self.args.data)}' error ❌ {e}")) from e
RuntimeError: Dataset '/blue/hulcr/gmarais/PhD/IBBI_work/phase_1_data/2_object_detection_phase_2/ultralytics/cv_iteration_2/data.yaml' error ❌ Dataset '/blue/hulcr/gmarais/PhD/IBBI_work/phase_1_data/2_object_detection_phase_2/ultralytics/cv_iteration_2/data.yaml' images not found, missing path '/blue/hulcr/gmarais/PhD/phase_1_data/2_object_detection_phase_2/ultralytics/cv_iteration_2/images/val'
Note dataset download directory is '/blue/hulcr/gmarais/PhD/phase_2_baseline/0_object_detection/8_rtdetr/train/datasets'. You can update this in '/home/gmarais/.config/Ultralytics/settings.json'
