2025-05-27 07:57:07 - Fold-4_GPU-0 - INFO - Initializing training for Fold 4 on GPU 0 with model rtdetr-x.pt.
2025-05-27 07:57:07 - Fold-4_GPU-0 - INFO - Data YAML: /blue/hulcr/gmarais/PhD/IBBI_work/phase_1_data/2_object_detection_phase_2/ultralytics/cv_iteration_4/data.yaml
2025-05-27 07:57:07 - Fold-4_GPU-0 - INFO - Ultralytics project dir (base for this fold's runs): ./results_rtdetr-x/fold_4
2025-05-27 07:57:07 - Fold-4_GPU-0 - INFO - Ultralytics run name (specific training run): rtdetr-x_e3_b16_imgsz640
2025-05-27 07:57:07 - Fold-4_GPU-0 - INFO - Python-level stdout and stderr for this fold (for Ultralytics) are now redirected to: ./results_rtdetr-x/fold_4/ultralytics_output_fold_4_gpu_0.log
2025-05-27 07:57:09 - Fold-4_GPU-0 - INFO - Loaded base model rtdetr-x.pt using ultralytics.RTDETR class.
2025-05-27 07:57:09 - Fold-4_GPU-0 - INFO - Starting Ultralytics training with effective hyperparameters: {'epochs': 3, 'batch': 16, 'workers': 3, 'patience': 0, 'close_mosaic': 50, 'cache': False, 'imgsz': 640, 'optimizer': 'AdamW', 'lr0': 0.0001, 'lrf': 0.01, 'weight_decay': 0.0001, 'dropout': 0.0, 'pretrained': True, 'resume': False, 'hsv_h': 0.015, 'hsv_s': 0.7, 'hsv_v': 0.4, 'degrees': 0.0, 'translate': 0.1, 'scale': 0.5, 'shear': 0.0, 'perspective': 0.0, 'flipud': 0.5, 'fliplr': 0.5, 'mosaic': 1.0, 'mixup': 0.0, 'copy_paste': 0.0, 'save': True, 'save_period': 1, 'exist_ok': True, 'verbose': True, 'seed': 0, 'project': './results_rtdetr-x/fold_4', 'name': 'rtdetr-x_e3_b16_imgsz640', 'data': '/blue/hulcr/gmarais/PhD/IBBI_work/phase_1_data/2_object_detection_phase_2/ultralytics/cv_iteration_4/data.yaml', 'device': '0'}
2025-05-27 07:57:09 - Fold-4_GPU-0 - ERROR - An error occurred during training for Fold-4_GPU-0: Dataset '/blue/hulcr/gmarais/PhD/IBBI_work/phase_1_data/2_object_detection_phase_2/ultralytics/cv_iteration_4/data.yaml' error ❌ Dataset '/blue/hulcr/gmarais/PhD/IBBI_work/phase_1_data/2_object_detection_phase_2/ultralytics/cv_iteration_4/data.yaml' images not found, missing path '/blue/hulcr/gmarais/PhD/phase_1_data/2_object_detection_phase_2/ultralytics/cv_iteration_4/images/val'
Note dataset download directory is '/blue/hulcr/gmarais/PhD/IBBI_work/phase_2_baseline/0_object_detect/8_rtdetr/train/datasets'. You can update this in '/home/gmarais/.config/Ultralytics/settings.json'
Traceback (most recent call last):
  File "/blue/hulcr/gmarais/conda/envs/EEL/lib/python3.11/site-packages/ultralytics/engine/trainer.py", line 587, in get_dataset
    data = check_det_dataset(self.args.data)
           ^^^^^^^^^^^^^^^^^^^^^^^^^^^^^^^^^
  File "/blue/hulcr/gmarais/conda/envs/EEL/lib/python3.11/site-packages/ultralytics/data/utils.py", line 454, in check_det_dataset
    raise FileNotFoundError(m)
FileNotFoundError: Dataset '/blue/hulcr/gmarais/PhD/IBBI_work/phase_1_data/2_object_detection_phase_2/ultralytics/cv_iteration_4/data.yaml' images not found, missing path '/blue/hulcr/gmarais/PhD/phase_1_data/2_object_detection_phase_2/ultralytics/cv_iteration_4/images/val'
Note dataset download directory is '/blue/hulcr/gmarais/PhD/IBBI_work/phase_2_baseline/0_object_detect/8_rtdetr/train/datasets'. You can update this in '/home/gmarais/.config/Ultralytics/settings.json'

The above exception was the direct cause of the following exception:

Traceback (most recent call last):
  File "/blue/hulcr/gmarais/PhD/IBBI_work/phase_2_baseline/0_object_detect/8_rtdetr/train/rtdetr_5fold.py", line 179, in train_single_fold
    results = model.train(**current_train_params)
              ^^^^^^^^^^^^^^^^^^^^^^^^^^^^^^^^^^^
  File "/blue/hulcr/gmarais/conda/envs/EEL/lib/python3.11/site-packages/ultralytics/engine/model.py", line 787, in train
    self.trainer = (trainer or self._smart_load("trainer"))(overrides=args, _callbacks=self.callbacks)
                   ^^^^^^^^^^^^^^^^^^^^^^^^^^^^^^^^^^^^^^^^^^^^^^^^^^^^^^^^^^^^^^^^^^^^^^^^^^^^^^^^^^^
  File "/blue/hulcr/gmarais/conda/envs/EEL/lib/python3.11/site-packages/ultralytics/engine/trainer.py", line 137, in __init__
    self.data = self.get_dataset()
                ^^^^^^^^^^^^^^^^^^
  File "/blue/hulcr/gmarais/conda/envs/EEL/lib/python3.11/site-packages/ultralytics/engine/trainer.py", line 591, in get_dataset
    raise RuntimeError(emojis(f"Dataset '{clean_url(self.args.data)}' error ❌ {e}")) from e
RuntimeError: Dataset '/blue/hulcr/gmarais/PhD/IBBI_work/phase_1_data/2_object_detection_phase_2/ultralytics/cv_iteration_4/data.yaml' error ❌ Dataset '/blue/hulcr/gmarais/PhD/IBBI_work/phase_1_data/2_object_detection_phase_2/ultralytics/cv_iteration_4/data.yaml' images not found, missing path '/blue/hulcr/gmarais/PhD/phase_1_data/2_object_detection_phase_2/ultralytics/cv_iteration_4/images/val'
Note dataset download directory is '/blue/hulcr/gmarais/PhD/IBBI_work/phase_2_baseline/0_object_detect/8_rtdetr/train/datasets'. You can update this in '/home/gmarais/.config/Ultralytics/settings.json'
2025-05-27 07:57:09 - Fold-4_GPU-0 - INFO - Restored stdout/stderr for this fold process.
